Workbook
Name Slicer_City: #N/A
Name Slicer_City1: #N/A
Name Slicer_Months: #N/A
Name Slicer_Months1: #N/A
Name Slicer_Payment_Method: #N/A
Name Slicer_Payment_Method1: #N/A

Sheet Customers
A1: Customer_ID | B1: Name | C1: Age | D1: City
A2: CUST-001 | B2: David Kiptoo | C2: 23 | D2: Eldoret
A3: CUST-002 | B3: James Odhiambo | C3: 60 | D3: Nakuru
A4: CUST-003 | B4: Mercy Njeri | C4: 26 | D4: Nairobi
A5: CUST-004 | B5: Mercy Njeri | C5: 42 | D5: Eldoret
A6: CUST-005 | B6: Peter Mutua | C6: 19 | D6: Kisumu
A7: CUST-006 | B7: Ann Wairimu | C7: 64 | D7: Nairobi
A8: CUST-007 | B8: Peter Mutua | C8: 44 | D8: Kisumu
A9: CUST-008 | B9: Faith Achieng | C9: 58 | D9: Nairobi
A10: CUST-009 | B10: Ann Wairimu | C10: 38 | D10: Nairobi
A11: CUST-010 | B11: Ann Wairimu | C11: 49 | D11: Nakuru
A12: CUST-011 | B12: Mary Wanjiku | C12: 48 | D12: Nairobi
A13: CUST-012 | B13: James Odhiambo | C13: 47 | D13: Nakuru
... A51: CUST-050 | B51: John Kamau | C51: 46 | D51: Nairobi

Sheet Products
A1: Product_ID | B1: Product_Name | C1: Category | D1: Price_KES
A2: PRD-001 | B2: Cooking Pot | C2: Home & Living | D2: 1780
A3: PRD-002 | B3: Smartphone | C3: Electronics | D3: 19883
A4: PRD-003 | B4: Ankara Dress | C4: Clothing | D4: 6948
A5: PRD-004 | B5: Ankara Dress | C5: Clothing | D5: 17614
A6: PRD-005 | B6: Sofa Set | C6: Home & Living | D6: 8875
A7: PRD-006 | B7: Hair Oil | C7: Beauty | D7: 13649
A8: PRD-007 | B8: Rice 5kg | C8: Groceries | D8: 11625
A9: PRD-008 | B9: Bluetooth Speaker | C9: Electronics | D9: 19088
A10: PRD-009 | B10: Rice 5kg | C10: Groceries | D10: 7963
A11: PRD-010 | B11: Maize Flour | C11: Groceries | D11: 18012
A12: PRD-011 | B12: Smartphone | C12: Electronics | D12: 5104
A13: PRD-012 | B13: Ankara Dress | C13: Clothing | D13: 19755
... A31: PRD-030 | B31: Maize Flour | C31: Groceries | D31: 8706

Sheet orders
A1: Order_ID | B1: Customer_ID | C1: Product_ID | D1: Order_Date | E1: Months | F1: Quantity | G1: Payment_Method | H1: City | I1: Price_KES | J1: Revenue_KES | K1: Total Revenue
A2: ORD-001 | B2: CUST-041 | C2: PRD-024 | D2: 29/06/2024 | E2: =TEXT(D2,"mmm") -> Jun | F2: 3 | G2: Cash | H2: =VLOOKUP(B2, Customers!A:D, 4, FALSE()) -> Kisumu | I2: =VLOOKUP(C2,Products!$A:$D,4,FALSE()) -> 15361 | J2: =I2*F2 -> 46083 | K2: =SUM(J2:J101) -> 3770677
A3: ORD-002 | B3: CUST-006 | C3: PRD-021 | D3: 29/10/2024 | E3: =TEXT(D3,"mmm") -> Oct | F3: 4 | G3: Airtel Money | H3: =VLOOKUP(B3, Customers!A:D, 4, FALSE()) -> Nairobi | I3: =VLOOKUP(C3,Products!$A:$D,4,FALSE()) -> 13313 | J3: =I3*F3 -> 53252
A4: ORD-003 | B4: CUST-041 | C4: PRD-021 | D4: 26/06/2024 | E4: =TEXT(D4,"mmm") -> Jun | F4: 2 | G4: M-Pesa | H4: =VLOOKUP(B4, Customers!A:D, 4, FALSE()) -> Kisumu | I4: =VLOOKUP(C4,Products!$A:$D,4,FALSE()) -> 13313 | J4: =I4*F4 -> 26626
A5: ORD-004 | B5: CUST-032 | C5: PRD-003 | D5: 20/06/2024 | E5: =TEXT(D5,"mmm") -> Jun | F5: 2 | G5: Airtel Money | H5: =VLOOKUP(B5, Customers!A:D, 4, FALSE()) -> Kisumu | I5: =VLOOKUP(C5,Products!$A:$D,4,FALSE()) -> 6948 | J5: =I5*F5 -> 13896
A6: ORD-005 | B6: CUST-034 | C6: PRD-006 | D6: 04/09/2024 | E6: =TEXT(D6,"mmm") -> Sept | F6: 3 | G6: M-Pesa | H6: =VLOOKUP(B6, Customers!A:D, 4, FALSE()) -> Eldoret | I6: =VLOOKUP(C6,Products!$A:$D,4,FALSE()) -> 13649 | J6: =I6*F6 -> 40947
A7: ORD-006 | B7: CUST-004 | C7: PRD-012 | D7: 13/01/2024 | E7: =TEXT(D7,"mmm") -> Jan | F7: 5 | G7: M-Pesa | H7: =VLOOKUP(B7, Customers!A:D, 4, FALSE()) -> Eldoret | I7: =VLOOKUP(C7,Products!$A:$D,4,FALSE()) -> 19755 | J7: =I7*F7 -> 98775
A8: ORD-007 | B8: CUST-046 | C8: PRD-026 | D8: 24/03/2024 | E8: =TEXT(D8,"mmm") -> Mar | F8: 4 | G8: Cash | H8: =VLOOKUP(B8, Customers!A:D, 4, FALSE()) -> Nairobi | I8: =VLOOKUP(C8,Products!$A:$D,4,FALSE()) -> 8822 | J8: =I8*F8 -> 35288
A9: ORD-008 | B9: CUST-042 | C9: PRD-027 | D9: 08/03/2024 | E9: =TEXT(D9,"mmm") -> Mar | F9: 4 | G9: M-Pesa | H9: =VLOOKUP(B9, Customers!A:D, 4, FALSE()) -> Mombasa | I9: =VLOOKUP(C9,Products!$A:$D,4,FALSE()) -> 7972 | J9: =I9*F9 -> 31888
A10: ORD-009 | B10: CUST-049 | C10: PRD-018 | D10: 26/07/2024 | E10: =TEXT(D10,"mmm") -> Jul | F10: 2 | G10: Card | H10: =VLOOKUP(B10, Customers!A:D, 4, FALSE()) -> Nakuru | I10: =VLOOKUP(C10,Products!$A:$D,4,FALSE()) -> 7552 | J10: =I10*F10 -> 15104
A11: ORD-010 | B11: CUST-048 | C11: PRD-002 | D11: 02/01/2024 | E11: =TEXT(D11,"mmm") -> Jan | F11: 5 | G11: M-Pesa | H11: =VLOOKUP(B11, Customers!A:D, 4, FALSE()) -> Kisumu | I11: =VLOOKUP(C11,Products!$A:$D,4,FALSE()) -> 19883 | J11: =I11*F11 -> 99415
A12: ORD-011 | B12: CUST-042 | C12: PRD-004 | D12: 19/03/2024 | E12: =TEXT(D12,"mmm") -> Mar | F12: 3 | G12: Card | H12: =VLOOKUP(B12, Customers!A:D, 4, FALSE()) -> Mombasa | I12: =VLOOKUP(C12,Products!$A:$D,4,FALSE()) -> 17614 | J12: =I12*F12 -> 52842
A13: ORD-012 | B13: CUST-039 | C13: PRD-024 | D13: 26/08/2024 | E13: =TEXT(D13,"mmm") -> Aug | F13: 5 | G13: M-Pesa | H13: =VLOOKUP(B13, Customers!A:D, 4, FALSE()) -> Kisumu | I13: =VLOOKUP(C13,Products!$A:$D,4,FALSE()) -> 15361 | J13: =I13*F13 -> 76805
A14: ORD-013 | B14: CUST-035 | C14: PRD-020 | D14: 18/04/2024 | E14: =TEXT(D14,"mmm") -> Apr | F14: 3 | G14: Airtel Money | H14: =VLOOKUP(B14, Customers!A:D, 4, FALSE()) -> Mombasa | I14: =VLOOKUP(C14,Products!$A:$D,4,FALSE()) -> 4746 | J14: =I14*F14 -> 14238
... A101: ORD-100 | B101: CUST-032 | C101: PRD-008 | D101: 26/06/2024 | E101: =TEXT(D101,"mmm") -> Jun | F101: 3 | G101: M-Pesa | H101: =VLOOKUP(B101, Customers!A:D, 4, FALSE()) -> Kisumu | I101: =VLOOKUP(C101,Products!$A:$D,4,FALSE()) -> 19088 | J101: =I101*F101 -> 57264

Sheet pivot table
A1: Row Labels | B1: Sum of Revenue_KES
A2: Jan | B2: 509580
A3: Feb | B3: 166307
A4: Mar | B4: 319770
A5: Apr | B5: 470015
A6: May | B6: 387405
A7: Jun | B7: 620237
A8: Jul | B8: 214014
A9: Aug | B9: 411743
A10: Sept | B10: 84698
A11: Oct | B11: 232181
A12: Nov | B12: 274414
A13: Dec | B13: 80313
A14: Grand Total | B14: 3770677
A20: Row Labels | B20: Sum of Revenue_KES
A21: Airtel Money | B21: 652276
A22: Card | B22: 1114621
A23: Cash | B23: 893559
A24: M-Pesa | B24: 1110221
A25: Grand Total | B25: 3770677
A35: Row Labels | B35: Sum of Revenue_KES
A36: Eldoret | B36: 426138
A37: Kisumu | B37: 784454
A38: Mombasa | B38: 737090
A39: Nairobi | B39: 1234995
A40: Nakuru | B40: 588000
A41: Grand Total | B41: 3770677
A50: Row Labels | B50: Sum of Revenue_KES
A51: PRD-001 | B51: 1780
A52: PRD-002 | B52: 119298
A53: PRD-003 | B53: 34740
A54: PRD-004 | B54: 457964
A55: PRD-005 | B55: 124250
A56: PRD-006 | B56: 95543
A57: PRD-007 | B57: 127875
A58: PRD-008 | B58: 343584
A59: PRD-009 | B59: 31852
A60: PRD-010 | B60: 180120
A61: PRD-011 | B61: 45936
A62: PRD-012 | B62: 177795
...

Sheet Dashboard
A1: Kenya E-Commerce Revenue Dashboard 2024
F2: KEY INSIGHTS
A3: KEY PERFOMANCE INDICATORS | F3: Top City | G3: Nairobi leads revenue at KES 1,234,995 — 33% of total. Focus marketing and stock here.
A4: Total Revenue | B4: Total orders | C4: Total Products | D4: Top month | F4: Peak Month | G4: June is the strongest month (KES 620,237).Mid-year sale spike
A5: =SUM(orders!J:J) -> 3770677 | B5: =COUNTA(orders!A:A)-1 -> 100 | C5: =COUNTA(Products!A:A)-1 -> 30 | D5: =INDEX('pivot table'!A2:A13,MATCH(MAX('pivot table'!B2:B13),'pivot table'!B2:B13,0)) -> Jun | F5: Best Payment | G5: Card & M-Pesa together make up 59% of revenue. Digital payments dominate
F6: Top Product | G6: PRD-013 (Ankara Dress) is the highest revenue product at KES 459,264. Major revenue driver
F7: Slow Month | G7: February & December are the weakest months. Consider discounts or campaigns to boost sales.
F8: Unsold Products | G8: PRD-016, PRD-019 & PRD-022 had zero orders. No demand recorded
